Workbook

Sheet List
B2: NAME | C2: ENGLISH NAME | D2: CODE
B3: =Links!B3 -> خليج الكوثر للتجاره والمقاولات | C3: =Links!C3 -> ALKAWTHER BAY COMPANY FOR TRADING AND CONTRACTING | D3: =Links!G3 -> A1
B4: =Links!B4 -> مؤسسه العماره الهندسيه | C4: =Links!C4 -> Engineering Architecture | D4: =Links!G4 -> E2
B5: =Links!B5 -> مؤسسه ورود حسن الكحيليني | C5: =Links!C5 -> Worod Hassan Al-Kahilini | D5: =Links!G5 -> W3
B6: =Links!B6 -> مؤسسه عبد العزيز أحمد الناصر | C6: =Links!C6 -> Abdul Aziz Ahmed Al Nasser | D6: =Links!G6 -> A4
B7: =Links!B7 -> مؤسسه انجاز الأثير للمقاولات | C7: =Links!C7 -> Injaz Al-Atheer Contracting | D7: =Links!G7 -> I5
B8: =Links!B8 -> مؤسسه خديجة صالح سالم البلوى | C8: Khadija Saleh Salem Al-Balawi60 | D8: =Links!G8 -> K6
B9: =Links!B9 -> مؤسسه تمارا المستقبل للصيانة | C9: =Links!C9 -> Tamara Al-Mustaqbal for Maintenance | D9: =Links!G9 -> T7
B10: =Links!B10 -> مؤسسه فلاح دريميح المطيرى | C10: =Links!C10 -> Falah Dreimeh Al-Mutairi | D10: =Links!G10 -> F8
B11: =Links!B11 -> مؤسسه سلسبيل الصفا للتشغيل والصيانة | C11: =Links!C11 -> Salsabeel Al-Safa for Operation and Maintenance | D11: =Links!G11 -> S9
B12: =Links!B12 -> البنائيين العرب | C12: =Links!C12 -> ACCC | D12: =Links!G12 -> A10
B13: =Links!B13 -> الخبرات العمالية | C13: =Links!C13 -> Global Expertise | D13: =Links!G13 -> G11
B14: =Links!B14 -> منظومة إعمار(لاغى) | C14: =Links!C14 -> Manzumat Emaar | D14: =Links!G14 -> M12
B15: =Links!B15 -> جوان الأولى | C15: =Links!C15 -> Giwan | D15: =Links!G15 -> G13
B16: =Links!B16 -> حسين (لاغى) | C16: =Links!C16 -> Hussain | D16: =Links!G16 -> H14
B17: =Links!B17 -> على السيد | C17: =Links!C17 -> Ali Elsayed | D17: =Links!G17 -> A15
B18: =Links!B18 -> أحمد عصام (لاغى ) | C18: =Links!C18 -> Ahmed Essam | D18: =Links!G18 -> A16
B19: =Links!B19 -> أحمد السوهاجى | C19: =Links!C19 -> Ahmed Elsohagy | D19: =Links!G19 -> A17
B20: =Links!B20 -> مؤسسة جاسم البحار (حوالة ) | C20: =Links!C20 -> Jasim Albihar | D20: =Links!G20 -> J18-MEP
... B400: =Links!B400 -> 0 | C400: =Links!C400 -> 0 | D400: =Links!G400 -> 0

Sheet Links
B2: NAME ARABIC | C2: NAME ENGLISH | D2: NO. | E2: FIRST LETTER | F2: CONTRACT CODE | G2: CODE | H2: اسم المؤسسة /الشركة | I2: المسمى بالانجليزي | J2: Time Start | K2: نطاق العمل | L2: اسم المقاول المفوض | M2: Zone | N2: رقم العقد | O2: Building | P2: Building | Q2: Building | R2: Building
B3: خليج الكوثر للتجاره والمقاولات | C3: ALKAWTHER BAY COMPANY FOR TRADING AND CONTRACTING | D3: 1 | E3: =LEFT(C3,1) -> A | F3: CSU | G3: A1 | H3: =B3 -> خليج الكوثر للتجاره والمقاولات | I3: =C3 -> ALKAWTHER BAY COMPANY FOR TRADING AND CONTRACTING | K3: حدادة ونجارة دق مسمار
B4: مؤسسه العماره الهندسيه | C4: Engineering Architecture | D4: 2 | E4: E | F4: CSB | G4: E2 | H4: =B4 -> مؤسسه العماره الهندسيه | I4: =C4 -> Engineering Architecture | J4: 45845 | K4: (خرسانة + طابوق ) مصنعيات بالعدة | L4: وليد | M4: 72 | O4: 3BHK (A-11) | P4: 3BHK (AS-2-12)
B5: مؤسسه ورود حسن الكحيليني | C5: Worod Hassan Al-Kahilini | D5: 3 | E5: W | F5: CSB | G5: W3 | H5: =B5 -> مؤسسه ورود حسن الكحيليني | I5: =C5 -> Worod Hassan Al-Kahilini | J5: 45847 | K5: (خرسانة + طابوق ) مصنعيات بالعدة | L5: شهباز | M5: 72 | N5: 103 - 2025-sama qamra | O5: 3BHK (AS1-7) | P5: 3BHK (A8) | Q5: 3BHK (AS2-9) | R5: 3BHK (AS1-10)
B6: مؤسسه عبد العزيز أحمد الناصر | C6: Abdul Aziz Ahmed Al Nasser | D6: 4 | E6: A | F6: CSB | G6: A4 | H6: =B6 -> مؤسسه عبد العزيز أحمد الناصر | I6: =C6 -> Abdul Aziz Ahmed Al Nasser | J6: 45866 | K6: (خرسانة + طابوق ) مصنعيات بالعدة | L6: زكريا | M6: 32 | N6: 105 - 2025-sama qamra | O6: 3BHK (AS-2-1) | P6: 3BHK (A-2)
B7: مؤسسه انجاز الأثير للمقاولات | C7: Injaz Al-Atheer Contracting | D7: 5 | E7: I | F7: CSB | G7: I5 | H7: =B7 -> مؤسسه انجاز الأثير للمقاولات | I7: =C7 -> Injaz Al-Atheer Contracting | J7: 45869 | K7: (خرسانة + طابوق ) مصنعيات بالعدة | L7: ابو رضوان | M7: 32 | N7: 106 - 2025-sama qamra | O7: 3BHK (A-5) | P7: 3BHK (AS-1-6)
B8: مؤسسه خديجة صالح سالم البلوى | C8: Khadija Saleh Salem Al-Balawi | D8: 6 | E8: K | F8: CSB | G8: K6 | H8: =B8 -> مؤسسه خديجة صالح سالم البلوى | I8: =C8 -> Khadija Saleh Salem Al-Balawi | J8: 45915 | K8: (خرسانة + طابوق ) مصنعيات بالعدة | L8: ابو عبد عزيز | M8: 33 | O8: 4BHK (B1) | P8: 4BHK (B2)
B9: مؤسسه تمارا المستقبل للصيانة | C9: Tamara Al-Mustaqbal for Maintenance | D9: 7 | E9: T | F9: CSB | G9: T7 | H9: =B9 -> مؤسسه تمارا المستقبل للصيانة | I9: =C9 -> Tamara Al-Mustaqbal for Maintenance | J9: 45922 | K9: (خرسانة + طابوق ) مصنعيات بالعدة | L9: ابو مروان | M9: 33 | N9: 114 - 2025-sama qamra | O9: 4BHK (B5) | P9: 4BHK (BS1-6)
B10: مؤسسه فلاح دريميح المطيرى | C10: Falah Dreimeh Al-Mutairi | D10: 8 | E10: F | F10: CSB | G10: F8 | H10: =B10 -> مؤسسه فلاح دريميح المطيرى | I10: =C10 -> Falah Dreimeh Al-Mutairi | J10: 45918 | K10: (خرسانة + طابوق ) مصنعيات بالعدة | L10: ابو الخير | M10: 33 | N10: 113 - 2025-sama qamra | O10: 4BHK (BS1-3) | P10: 4BHK (BS2-4)
B11: مؤسسه سلسبيل الصفا للتشغيل والصيانة | C11: Salsabeel Al-Safa for Operation and Maintenance | D11: 9 | E11: S | F11: BAFI | G11: S9 | H11: =B11 -> مؤسسه سلسبيل الصفا للتشغيل والصيانة | I11: =C11 -> Salsabeel Al-Safa for Operation and Maintenance | J11: 45794 | K11: حفر & احلال | L11: ابو محمد | M11: All | N11: 100- 2025-sama qamra
B12: البنائيين العرب | C12: ACCC | D12: 10 | E12: A | F12: INS | G12: A10 | H12: =B12 -> البنائيين العرب | I12: =C12 -> ACCC | J12: 45909 | K12: عزل (بيتومين - اسمنتي - اسطح) | L12: م-عادل عرفة | M12: All
B13: الخبرات العمالية | C13: Global Expertise | D13: 11 | E13: G | F13: CSB | G13: G11 | H13: =B13 -> الخبرات العمالية | I13: =C13 -> Global Expertise | J13: 45935 | K13: (خرسانة + طابوق ) مصنعيات بالعدة | L13: مقيد السورى | M13: 33 | N13: 115 - 2025-sama qamra | O13: 4BHK (B2) | P13: 4BHK (B1) | Q13: 4BHK (B8)
B14: منظومة إعمار(لاغى) | C14: Manzumat Emaar | D14: 12 | E14: M | F14: CSB | G14: M12 | H14: =B14 -> منظومة إعمار(لاغى) | I14: =C14 -> Manzumat Emaar | K14: (خرسانة + طابوق ) مصنعيات بالعدة | L14: خيرى | M14: 33 | O14: 4BHK (B9)
B15: جوان الأولى | C15: Giwan | D15: 13 | E15: G | F15: CSB | G15: G13 | H15: =B15 -> جوان الأولى | I15: =C15 -> Giwan | J15: 45935 | K15: (خرسانة + طابوق ) مصنعيات بالعدة | L15: محمد فودة الإحساء | M15: 33 | N15: 116 - 2025-sama qamra | O15: 4BHK (BS2-7)
B16: حسين (لاغى) | C16: Hussain | D16: 14 | E16: H | F16: SHSU | G16: H14 | H16: =B16 -> حسين (لاغى) | I16: =C16 -> Hussain | K16: نجارة دق مسمار | L16: حسين + أحمد عبد العظيم | M16: 32 | O16: 3BHK (AS-2-4)
B17: على السيد | C17: Ali Elsayed | D17: 15 | E17: A | F17: SHSU | G17: A15 | H17: =B17 -> على السيد | I17: =C17 -> Ali Elsayed | J17: 45939 | K17: نجارة دق مسمار | L17: على السيد | M17: 72 | O17: 3BHK (AS1-7) | P17: 3BHK (A8) | Q17: 3BHK (AS2-9)
B18: أحمد عصام (لاغى ) | C18: Ahmed Essam | D18: 16 | E18: A | F18: SHSU | G18: A16 | H18: =B18 -> أحمد عصام (لاغى ) | I18: =C18 -> Ahmed Essam | K18: نجارة دق مسمار | L18: أحمد عصام | M18: 72 | O18: 3BHK (AS1-10) | P18: 3BHK (A-11) | Q18: 3BHK (AS-2-12)
B19: أحمد السوهاجى | C19: Ahmed Elsohagy | D19: 17 | E19: A | F19: CSU | G19: A17 | H19: =B19 -> أحمد السوهاجى | I19: =C19 -> Ahmed Elsohagy | J19: 45993 | K19: حدادة ونجارة دق مسمار | L19: أحمد السوهاجى | M19: 33 | O19: 3BHK (A8)
B20: مؤسسة جاسم البحار (حوالة ) | C20: Jasim Albihar | D20: 18-MEP | E20: J | F20: MEPU | G20: J18-MEP | H20: =B20 -> مؤسسة جاسم البحار (حوالة ) | I20: =C20 -> Jasim Albihar | J20: 45976 | K20: كهرباء وميكانيكا مصنعيات | L20: الفلبينى | M20: 32 | N20: 005 - elec & mech -2025 sama Qamra | O20: 3BHK (AS-2-4) | P20: 3BHK (AS-1-3)
B21: مهندس كريم (لاغى) | C21: Engineer Karim | D21: 19-MEP | E21: E | F21: MEPU | G21: E19-MEP | H21: =B21 -> مهندس كريم (لاغى) | I21: =C21 -> Engineer Karim | K21: كهرباء وميكانيكا مصنعيات | L21: مهندس كريم | M21: 32 | O21: 3BHK (A-5) | P21: 3BHK (AS-1-6)
B22: شركة الرحاب ( لاغى) | C22: El-Rehab Company | D22: 20-MEP | E22: E | F22: MEPU | G22: E20-MEP | H22: =B22 -> شركة الرحاب ( لاغى) | I22: =C22 -> El-Rehab Company | K22: كهرباء وميكانيكا مصنعيات | M22: 33 | O22: 4BHK (B2) | P22: 4BHK (B5) | Q22: 4BHK (BS1-6)
B23: سعد يونس (كاش) - المجرة الشرقية | C23: Saad Younis | D23: 21-MEP | E23: S | F23: MEPU | G23: S21-MEP | H23: =B23 -> سعد يونس (كاش) - المجرة الشرقية | I23: =C23 -> Saad Younis | K23: كهرباء وميكانيكا مصنعيات | L23: سعد يونس | M23: 32 | O23: 3BHK (AS-2-1) | P23: 3BHK (A2)
D24: 13-MEP | G24: 0 | H24: =B24 -> 0 | I24: =C24 -> 0 | K24: كهرباء وميكانيكا مصنعيات | L24: محمد فودة الإحساء | M24: 33 | O24: 4BHK (BS2-7)
B25: الخبرات العمالية (حوالة ) | C25: Global Expertise | D25: 23-MEP | E25: G | F25: MEPU | G25: G23-MEP | H25: =B25 -> الخبرات العمالية (حوالة ) | I25: =C25 -> Global Expertise | J25: 45935 | K25: كهرباء وميكانيكا مصنعيات | L25: مقيد السورى | M25: 33 | N25: 004 - elec & mech - 2025 - sama qamra | O25: 4BHK (B1) | P25: 4BHK (B8)
B26: المتمكن للمقاولات(حوالة ) | C26: Tamkeen Contracting Company | D26: 24-MEP | E26: T | F26: MEPU | G26: T24-MEP | H26: =B26 -> المتمكن للمقاولات(حوالة ) | I26: =C26 -> Tamkeen Contracting Company | J26: 45976 | K26: كهرباء وميكانيكا مصنعيات | L26: سلطان الرشيد | M26: 33 | N26: 006 - Elec & mech -2025 - sama qamra | O26: 4BHK (BS2-7)
B27: مؤسسه فلاح دريميح المطيرى(لاغي) | C27: Falah Dreimeh Al-Mutairi | D27: 25-MEP | E27: F | F27: MEPU | G27: F25-MEP | H27: =B27 -> مؤسسه فلاح دريميح المطيرى(لاغي) | I27: =C27 -> Falah Dreimeh Al-Mutairi | K27: كهرباء وميكانيكا مصنعيات | L27: ابو الخير | M27: 33 | O27: 4BHK (BS1-3) | P27: 4BHK (BS2-4)
B28: مؤسسه تمارا المستقبل للصيانة (لاغي) | C28: Tamara Al-Mustaqbal for Maintenance | D28: 26-MEP | E28: T | F28: MEPU | G28: T26-MEP | H28: =B28 -> مؤسسه تمارا المستقبل للصيانة (لاغي) | I28: =C28 -> Tamara Al-Mustaqbal for Maintenance | K28: كهرباء وميكانيكا مصنعيات | L28: ابو مروان | M28: 33 | O28: 4BHK (B5) | P28: 4BHK (BS1-6)
B29: جوان الأولى(لاغي ) | C29: Jowan Al-Oula | D29: 27-MEP | E29: J | F29: MEPU | G29: J27-MEP | H29: =B29 -> جوان الأولى(لاغي ) | I29: =C29 -> Jowan Al-Oula | K29: كهرباء وميكانيكا مصنعيات | M29: 33 | O29: 4BHK (BS2-7)
B30: خليج الكوثر للتجاره والمقاولات MEP | C30: ALKAWTHER BAY COMPANY FOR TRADING AND CONTRACTING | D30: 28-MEP | E30: A | F30: MEPU | G30: A28-MEP | H30: =B30 -> خليج الكوثر للتجاره والمقاولات MEP | I30: =C30 -> ALKAWTHER BAY COMPANY FOR TRADING AND CONTRACTING | K30: كهرباء وميكانيكا مصنعيات
B31: جمال | C31: Gamal | D31: 29 | E31: G | F31: CSU | G31: G29 | H31: =B31 -> جمال | I31: =C31 -> Gamal | J31: 45972 | K31: حدادة ونجارة دق مسمار | L31: جمال | M31: 33 | O31: 4BHK (B5) | P31: 4BHK (BS1-6)
B32: مؤسسة فاطمة العليانى | C32: Fatma AlEliany | D32: 30 | E32: F | F32: CSB | G32: F30 | H32: =B32 -> مؤسسة فاطمة العليانى | I32: =C32 -> Fatma AlEliany | J32: 45976 | K32: (خرسانة + طابوق ) مصنعيات بالعدة | L32: أبو جنى - أبو خالد | M32: 32 | N32: 117 - 2025-sama qamra | O32: 3BHK (AS-1-3)
B33: محمد عبد الله سيد بركات ( روعة) - كاش Mep | C33: Rawaa | D33: 31-MEP | E33: R | F33: MEPU | G33: R31-MEP | H33: =B33 -> محمد عبد الله سيد بركات ( روعة) - كاش Mep | I33: =C33 -> Rawaa | J33: 45976 | K33: كهرباء وميكانيكا مصنعيات | M33: 72-32-33 | O33: FF ALL | P33: 4BHK (BS1-6) | Q33: 4BHK (BS2-4) | R33: 4BHK (BS1-3)
B34: محمد مجاهد (لاغى) | C34: Mohamed Mejahed | D34: 32-B | E34: M | F34: STSU | G34: M32-B | H34: =B34 -> محمد مجاهد (لاغى) | I34: =C34 -> Mohamed Mejahed | J34: 45976 | K34: حدادة دق مسار | M34: 72 | O34: AS 2-9
B35: إسماعيل | C35: Ismail | D35: 33-B | E35: I | F35: BU | G35: I33-B | H35: =B35 -> إسماعيل | I35: =C35 -> Ismail | J35: 45984 | K35: أعمال مباني مصنعيات | L35: إسماعيل | M35: 72 | O35: 3BHK (AS1-7)
B36: الخبرات العمالية ( بلوك) - مقيد | C36: Mokaid | D36: 34-B | E36: M | F36: BU | G36: M34-B | H36: =B36 -> الخبرات العمالية ( بلوك) - مقيد | I36: =C36 -> Mokaid | J36: 45964 | K36: أعمال مباني مصنعيات | L36: مقيد | M36: 72 | O36: 3BHK (A8)
B37: كمال- (بلوك) | C37: Kamal | D37: 35-B | E37: K | F37: BU | G37: K35-B | H37: =B37 -> كمال- (بلوك) | I37: =C37 -> Kamal | J37: 45998 | K37: أعمال مباني مصنعيات | L37: كمال | M37: 72 | O37: 3BHK (AS-2-12)
B38: عبد الملك( بلوك) /شهباز | C38: Abdelmalek / Shahbaz | D38: 36-B | E38: A | F38: BU | G38: A36-B | H38: =B38 -> عبد الملك( بلوك) /شهباز | I38: =C38 -> Abdelmalek / Shahbaz | J38: 45985 | K38: أعمال مباني مصنعيات | L38: عبد الملك | M38: 32 | O38: 3BHK (AS-2-4)
B39: مالك( بلوك) ( لاغى) | C39: Malek | D39: 37-B | E39: M | F39: BU | G39: M37-B | H39: =B39 -> مالك( بلوك) ( لاغى) | I39: =C39 -> Malek | K39: أعمال مباني مصنعيات | L39: مالك | M39: 72 | O39: 3BHK (A8)
B40: محمد محى (كاش)(أكبر) | C40: Mohamed Mohy | D40: 38-MEP | E40: M | F40: MEPU | G40: M38-MEP | H40: =B40 -> محمد محى (كاش)(أكبر) | I40: =C40 -> Mohamed Mohy | K40: كهرباء وميكانيكا مصنعيات | L40: محمد محى | M40: 72 | O40: 3BHK (AS1-10) | P40: 3BHK (A-11) | Q40: 3BHK (AS-2-12)
D41: 39 | G41: 0 | H41: =B41 -> 0 | I41: =C41 -> 0
...

Sheet Main and Sub Contractor Matrix
A2: VLOOKUP VALUE | C2: =C1+1 -> 1 | D2: =C2+1 -> 2 | E2: =D2+1 -> 3 | F2: =E2+1 -> 4 | G2: =F2+1 -> 5 | H2: =G2+1 -> 6 | I2: =H2+1 -> 7 | J2: =I2+1 -> 8 | K2: =J2+1 -> 9 | ... AR2: =AQ2+1 -> 42
C3: =VLOOKUP(C2,$A$4:$B$77,2,0) -> A1 | D3: =VLOOKUP(D2,$A$4:$B$77,2,0) -> E2 | E3: =VLOOKUP(E2,$A$4:$B$77,2,0) -> W3 | F3: =VLOOKUP(F2,$A$4:$B$77,2,0) -> A4 | G3: =VLOOKUP(G2,$A$4:$B$77,2,0) -> I5 | H3: =VLOOKUP(H2,$A$4:$B$77,2,0) -> K6 | I3: =VLOOKUP(I2,$A$4:$B$77,2,0) -> T7 | J3: =VLOOKUP(J2,$A$4:$B$77,2,0) -> F8 | ... AR3: =VLOOKUP(AR2,$A$4:$B$77,2,0) -> M42
A4: =1 -> 1 | B4: =Links!G3 -> A1 | C4: =IF(OR($B4=0,C$3=0),"",_xlfn.CONCAT($B4,VLOOKUP(C$2,$A$4:$B$70,2,0))) -> A1A1 | D4: =IF(OR($B4=0,D$3=0),"",_xlfn.CONCAT($B4,VLOOKUP(D$2,$A$4:$B$70,2,0))) -> A1E2 | E4: =IF(OR($B4=0,E$3=0),"",_xlfn.CONCAT($B4,VLOOKUP(E$2,$A$4:$B$70,2,0))) -> A1W3 | F4: =IF(OR($B4=0,F$3=0),"",_xlfn.CONCAT($B4,VLOOKUP(F$2,$A$4:$B$70,2,0))) -> A1A4 | G4: =IF(OR($B4=0,G$3=0),"",_xlfn.CONCAT($B4,VLOOKUP(G$2,$A$4:$B$70,2,0))) -> A1I5 | H4: =IF(OR($B4=0,H$3=0),"",_xlfn.CONCAT($B4,VLOOKUP(H$2,$A$4:$B$70,2,0))) -> A1K6 | I4: =IF(OR($B4=0,I$3=0),"",_xlfn.CONCAT($B4,VLOOKUP(I$2,$A$4:$B$70,2,0))) -> A1T7 | J4: =IF(OR($B4=0,J$3=0),"",_xlfn.CONCAT($B4,VLOOKUP(J$2,$A$4:$B$70,2,0))) -> A1F8 | ... AV4: =IF(OR($B4=0,AV$3=0),"",_xlfn.CONCAT($B4,VLOOKUP(AV$2,$A$4:$B$70,2,0)))
A5: =A4+1 -> 2 | B5: =Links!G4 -> E2 | C5: =IF(OR($B5=0,C$3=0),"",_xlfn.CONCAT($B5,VLOOKUP(C$2,$A$4:$B$70,2,0))) -> E2A1 | D5: =IF(OR($B5=0,D$3=0),"",_xlfn.CONCAT($B5,VLOOKUP(D$2,$A$4:$B$70,2,0))) -> E2E2 | E5: =IF(OR($B5=0,E$3=0),"",_xlfn.CONCAT($B5,VLOOKUP(E$2,$A$4:$B$70,2,0))) -> E2W3 | F5: =IF(OR($B5=0,F$3=0),"",_xlfn.CONCAT($B5,VLOOKUP(F$2,$A$4:$B$70,2,0))) -> E2A4 | G5: =IF(OR($B5=0,G$3=0),"",_xlfn.CONCAT($B5,VLOOKUP(G$2,$A$4:$B$70,2,0))) -> E2I5 | H5: =IF(OR($B5=0,H$3=0),"",_xlfn.CONCAT($B5,VLOOKUP(H$2,$A$4:$B$70,2,0))) -> E2K6 | I5: =IF(OR($B5=0,I$3=0),"",_xlfn.CONCAT($B5,VLOOKUP(I$2,$A$4:$B$70,2,0))) -> E2T7 | J5: =IF(OR($B5=0,J$3=0),"",_xlfn.CONCAT($B5,VLOOKUP(J$2,$A$4:$B$70,2,0))) -> E2F8 | ... AV5: =IF(OR($B5=0,AV$3=0),"",_xlfn.CONCAT($B5,VLOOKUP(AV$2,$A$4:$B$70,2,0)))
A6: =A5+1 -> 3 | B6: =Links!G5 -> W3 | C6: =IF(OR($B6=0,C$3=0),"",_xlfn.CONCAT($B6,VLOOKUP(C$2,$A$4:$B$70,2,0))) -> W3A1 | D6: =IF(OR($B6=0,D$3=0),"",_xlfn.CONCAT($B6,VLOOKUP(D$2,$A$4:$B$70,2,0))) -> W3E2 | E6: =IF(OR($B6=0,E$3=0),"",_xlfn.CONCAT($B6,VLOOKUP(E$2,$A$4:$B$70,2,0))) -> W3W3 | F6: =IF(OR($B6=0,F$3=0),"",_xlfn.CONCAT($B6,VLOOKUP(F$2,$A$4:$B$70,2,0))) -> W3A4 | G6: =IF(OR($B6=0,G$3=0),"",_xlfn.CONCAT($B6,VLOOKUP(G$2,$A$4:$B$70,2,0))) -> W3I5 | H6: =IF(OR($B6=0,H$3=0),"",_xlfn.CONCAT($B6,VLOOKUP(H$2,$A$4:$B$70,2,0))) -> W3K6 | I6: =IF(OR($B6=0,I$3=0),"",_xlfn.CONCAT($B6,VLOOKUP(I$2,$A$4:$B$70,2,0))) -> W3T7 | J6: =IF(OR($B6=0,J$3=0),"",_xlfn.CONCAT($B6,VLOOKUP(J$2,$A$4:$B$70,2,0))) -> W3F8 | ... AV6: =IF(OR($B6=0,AV$3=0),"",_xlfn.CONCAT($B6,VLOOKUP(AV$2,$A$4:$B$70,2,0)))
A7: =A6+1 -> 4 | B7: =Links!G6 -> A4 | C7: =IF(OR($B7=0,C$3=0),"",_xlfn.CONCAT($B7,VLOOKUP(C$2,$A$4:$B$70,2,0))) -> A4A1 | D7: =IF(OR($B7=0,D$3=0),"",_xlfn.CONCAT($B7,VLOOKUP(D$2,$A$4:$B$70,2,0))) -> A4E2 | E7: =IF(OR($B7=0,E$3=0),"",_xlfn.CONCAT($B7,VLOOKUP(E$2,$A$4:$B$70,2,0))) -> A4W3 | F7: =IF(OR($B7=0,F$3=0),"",_xlfn.CONCAT($B7,VLOOKUP(F$2,$A$4:$B$70,2,0))) -> A4A4 | G7: =IF(OR($B7=0,G$3=0),"",_xlfn.CONCAT($B7,VLOOKUP(G$2,$A$4:$B$70,2,0))) -> A4I5 | H7: =IF(OR($B7=0,H$3=0),"",_xlfn.CONCAT($B7,VLOOKUP(H$2,$A$4:$B$70,2,0))) -> A4K6 | I7: =IF(OR($B7=0,I$3=0),"",_xlfn.CONCAT($B7,VLOOKUP(I$2,$A$4:$B$70,2,0))) -> A4T7 | J7: =IF(OR($B7=0,J$3=0),"",_xlfn.CONCAT($B7,VLOOKUP(J$2,$A$4:$B$70,2,0))) -> A4F8 | ... AV7: =IF(OR($B7=0,AV$3=0),"",_xlfn.CONCAT($B7,VLOOKUP(AV$2,$A$4:$B$70,2,0)))
A8: =A7+1 -> 5 | B8: =Links!G7 -> I5 | C8: =IF(OR($B8=0,C$3=0),"",_xlfn.CONCAT($B8,VLOOKUP(C$2,$A$4:$B$70,2,0))) -> I5A1 | D8: =IF(OR($B8=0,D$3=0),"",_xlfn.CONCAT($B8,VLOOKUP(D$2,$A$4:$B$70,2,0))) -> I5E2 | E8: =IF(OR($B8=0,E$3=0),"",_xlfn.CONCAT($B8,VLOOKUP(E$2,$A$4:$B$70,2,0))) -> I5W3 | F8: =IF(OR($B8=0,F$3=0),"",_xlfn.CONCAT($B8,VLOOKUP(F$2,$A$4:$B$70,2,0))) -> I5A4 | G8: =IF(OR($B8=0,G$3=0),"",_xlfn.CONCAT($B8,VLOOKUP(G$2,$A$4:$B$70,2,0))) -> I5I5 | H8: =IF(OR($B8=0,H$3=0),"",_xlfn.CONCAT($B8,VLOOKUP(H$2,$A$4:$B$70,2,0))) -> I5K6 | I8: =IF(OR($B8=0,I$3=0),"",_xlfn.CONCAT($B8,VLOOKUP(I$2,$A$4:$B$70,2,0))) -> I5T7 | J8: =IF(OR($B8=0,J$3=0),"",_xlfn.CONCAT($B8,VLOOKUP(J$2,$A$4:$B$70,2,0))) -> I5F8 | ... AV8: =IF(OR($B8=0,AV$3=0),"",_xlfn.CONCAT($B8,VLOOKUP(AV$2,$A$4:$B$70,2,0)))
A9: =A8+1 -> 6 | B9: =Links!G8 -> K6 | C9: =IF(OR($B9=0,C$3=0),"",_xlfn.CONCAT($B9,VLOOKUP(C$2,$A$4:$B$70,2,0))) -> K6A1 | D9: =IF(OR($B9=0,D$3=0),"",_xlfn.CONCAT($B9,VLOOKUP(D$2,$A$4:$B$70,2,0))) -> K6E2 | E9: =IF(OR($B9=0,E$3=0),"",_xlfn.CONCAT($B9,VLOOKUP(E$2,$A$4:$B$70,2,0))) -> K6W3 | F9: =IF(OR($B9=0,F$3=0),"",_xlfn.CONCAT($B9,VLOOKUP(F$2,$A$4:$B$70,2,0))) -> K6A4 | G9: =IF(OR($B9=0,G$3=0),"",_xlfn.CONCAT($B9,VLOOKUP(G$2,$A$4:$B$70,2,0))) -> K6I5 | H9: =IF(OR($B9=0,H$3=0),"",_xlfn.CONCAT($B9,VLOOKUP(H$2,$A$4:$B$70,2,0))) -> K6K6 | I9: =IF(OR($B9=0,I$3=0),"",_xlfn.CONCAT($B9,VLOOKUP(I$2,$A$4:$B$70,2,0))) -> K6T7 | J9: =IF(OR($B9=0,J$3=0),"",_xlfn.CONCAT($B9,VLOOKUP(J$2,$A$4:$B$70,2,0))) -> K6F8 | ... AV9: =IF(OR($B9=0,AV$3=0),"",_xlfn.CONCAT($B9,VLOOKUP(AV$2,$A$4:$B$70,2,0)))
A10: =A9+1 -> 7 | B10: =Links!G9 -> T7 | C10: =IF(OR($B10=0,C$3=0),"",_xlfn.CONCAT($B10,VLOOKUP(C$2,$A$4:$B$70,2,0))) -> T7A1 | D10: =IF(OR($B10=0,D$3=0),"",_xlfn.CONCAT($B10,VLOOKUP(D$2,$A$4:$B$70,2,0))) -> T7E2 | E10: =IF(OR($B10=0,E$3=0),"",_xlfn.CONCAT($B10,VLOOKUP(E$2,$A$4:$B$70,2,0))) -> T7W3 | F10: =IF(OR($B10=0,F$3=0),"",_xlfn.CONCAT($B10,VLOOKUP(F$2,$A$4:$B$70,2,0))) -> T7A4 | G10: =IF(OR($B10=0,G$3=0),"",_xlfn.CONCAT($B10,VLOOKUP(G$2,$A$4:$B$70,2,0))) -> T7I5 | H10: =IF(OR($B10=0,H$3=0),"",_xlfn.CONCAT($B10,VLOOKUP(H$2,$A$4:$B$70,2,0))) -> T7K6 | I10: =IF(OR($B10=0,I$3=0),"",_xlfn.CONCAT($B10,VLOOKUP(I$2,$A$4:$B$70,2,0))) -> T7T7 | J10: =IF(OR($B10=0,J$3=0),"",_xlfn.CONCAT($B10,VLOOKUP(J$2,$A$4:$B$70,2,0))) -> T7F8 | ... AV10: =IF(OR($B10=0,AV$3=0),"",_xlfn.CONCAT($B10,VLOOKUP(AV$2,$A$4:$B$70,2,0)))
A11: =A10+1 -> 8 | B11: =Links!G10 -> F8 | C11: =IF(OR($B11=0,C$3=0),"",_xlfn.CONCAT($B11,VLOOKUP(C$2,$A$4:$B$70,2,0))) -> F8A1 | D11: =IF(OR($B11=0,D$3=0),"",_xlfn.CONCAT($B11,VLOOKUP(D$2,$A$4:$B$70,2,0))) -> F8E2 | E11: =IF(OR($B11=0,E$3=0),"",_xlfn.CONCAT($B11,VLOOKUP(E$2,$A$4:$B$70,2,0))) -> F8W3 | F11: =IF(OR($B11=0,F$3=0),"",_xlfn.CONCAT($B11,VLOOKUP(F$2,$A$4:$B$70,2,0))) -> F8A4 | G11: =IF(OR($B11=0,G$3=0),"",_xlfn.CONCAT($B11,VLOOKUP(G$2,$A$4:$B$70,2,0))) -> F8I5 | H11: =IF(OR($B11=0,H$3=0),"",_xlfn.CONCAT($B11,VLOOKUP(H$2,$A$4:$B$70,2,0))) -> F8K6 | I11: =IF(OR($B11=0,I$3=0),"",_xlfn.CONCAT($B11,VLOOKUP(I$2,$A$4:$B$70,2,0))) -> F8T7 | J11: =IF(OR($B11=0,J$3=0),"",_xlfn.CONCAT($B11,VLOOKUP(J$2,$A$4:$B$70,2,0))) -> F8F8 | ... AV11: =IF(OR($B11=0,AV$3=0),"",_xlfn.CONCAT($B11,VLOOKUP(AV$2,$A$4:$B$70,2,0)))
A12: =A11+1 -> 9 | B12: =Links!G11 -> S9 | C12: =IF(OR($B12=0,C$3=0),"",_xlfn.CONCAT($B12,VLOOKUP(C$2,$A$4:$B$70,2,0))) -> S9A1 | D12: =IF(OR($B12=0,D$3=0),"",_xlfn.CONCAT($B12,VLOOKUP(D$2,$A$4:$B$70,2,0))) -> S9E2 | E12: =IF(OR($B12=0,E$3=0),"",_xlfn.CONCAT($B12,VLOOKUP(E$2,$A$4:$B$70,2,0))) -> S9W3 | F12: =IF(OR($B12=0,F$3=0),"",_xlfn.CONCAT($B12,VLOOKUP(F$2,$A$4:$B$70,2,0))) -> S9A4 | G12: =IF(OR($B12=0,G$3=0),"",_xlfn.CONCAT($B12,VLOOKUP(G$2,$A$4:$B$70,2,0))) -> S9I5 | H12: =IF(OR($B12=0,H$3=0),"",_xlfn.CONCAT($B12,VLOOKUP(H$2,$A$4:$B$70,2,0))) -> S9K6 | I12: =IF(OR($B12=0,I$3=0),"",_xlfn.CONCAT($B12,VLOOKUP(I$2,$A$4:$B$70,2,0))) -> S9T7 | J12: =IF(OR($B12=0,J$3=0),"",_xlfn.CONCAT($B12,VLOOKUP(J$2,$A$4:$B$70,2,0))) -> S9F8 | ... AV12: =IF(OR($B12=0,AV$3=0),"",_xlfn.CONCAT($B12,VLOOKUP(AV$2,$A$4:$B$70,2,0)))
A13: =A12+1 -> 10 | B13: =Links!G12 -> A10 | C13: =IF(OR($B13=0,C$3=0),"",_xlfn.CONCAT($B13,VLOOKUP(C$2,$A$4:$B$70,2,0))) -> A10A1 | D13: =IF(OR($B13=0,D$3=0),"",_xlfn.CONCAT($B13,VLOOKUP(D$2,$A$4:$B$70,2,0))) -> A10E2 | E13: =IF(OR($B13=0,E$3=0),"",_xlfn.CONCAT($B13,VLOOKUP(E$2,$A$4:$B$70,2,0))) -> A10W3 | F13: =IF(OR($B13=0,F$3=0),"",_xlfn.CONCAT($B13,VLOOKUP(F$2,$A$4:$B$70,2,0))) -> A10A4 | G13: =IF(OR($B13=0,G$3=0),"",_xlfn.CONCAT($B13,VLOOKUP(G$2,$A$4:$B$70,2,0))) -> A10I5 | H13: =IF(OR($B13=0,H$3=0),"",_xlfn.CONCAT($B13,VLOOKUP(H$2,$A$4:$B$70,2,0))) -> A10K6 | I13: =IF(OR($B13=0,I$3=0),"",_xlfn.CONCAT($B13,VLOOKUP(I$2,$A$4:$B$70,2,0))) -> A10T7 | J13: =IF(OR($B13=0,J$3=0),"",_xlfn.CONCAT($B13,VLOOKUP(J$2,$A$4:$B$70,2,0))) -> A10F8 | ... AV13: =IF(OR($B13=0,AV$3=0),"",_xlfn.CONCAT($B13,VLOOKUP(AV$2,$A$4:$B$70,2,0)))
A14: =A13+1 -> 11 | B14: =Links!G13 -> G11 | C14: =IF(OR($B14=0,C$3=0),"",_xlfn.CONCAT($B14,VLOOKUP(C$2,$A$4:$B$70,2,0))) -> G11A1 | D14: =IF(OR($B14=0,D$3=0),"",_xlfn.CONCAT($B14,VLOOKUP(D$2,$A$4:$B$70,2,0))) -> G11E2 | E14: =IF(OR($B14=0,E$3=0),"",_xlfn.CONCAT($B14,VLOOKUP(E$2,$A$4:$B$70,2,0))) -> G11W3 | F14: =IF(OR($B14=0,F$3=0),"",_xlfn.CONCAT($B14,VLOOKUP(F$2,$A$4:$B$70,2,0))) -> G11A4 | G14: =IF(OR($B14=0,G$3=0),"",_xlfn.CONCAT($B14,VLOOKUP(G$2,$A$4:$B$70,2,0))) -> G11I5 | H14: =IF(OR($B14=0,H$3=0),"",_xlfn.CONCAT($B14,VLOOKUP(H$2,$A$4:$B$70,2,0))) -> G11K6 | I14: =IF(OR($B14=0,I$3=0),"",_xlfn.CONCAT($B14,VLOOKUP(I$2,$A$4:$B$70,2,0))) -> G11T7 | J14: =IF(OR($B14=0,J$3=0),"",_xlfn.CONCAT($B14,VLOOKUP(J$2,$A$4:$B$70,2,0))) -> G11F8 | ... AV14: =IF(OR($B14=0,AV$3=0),"",_xlfn.CONCAT($B14,VLOOKUP(AV$2,$A$4:$B$70,2,0)))
A15: =A14+1 -> 12 | B15: =Links!G14 -> M12 | C15: =IF(OR($B15=0,C$3=0),"",_xlfn.CONCAT($B15,VLOOKUP(C$2,$A$4:$B$70,2,0))) -> M12A1 | D15: =IF(OR($B15=0,D$3=0),"",_xlfn.CONCAT($B15,VLOOKUP(D$2,$A$4:$B$70,2,0))) -> M12E2 | E15: =IF(OR($B15=0,E$3=0),"",_xlfn.CONCAT($B15,VLOOKUP(E$2,$A$4:$B$70,2,0))) -> M12W3 | F15: =IF(OR($B15=0,F$3=0),"",_xlfn.CONCAT($B15,VLOOKUP(F$2,$A$4:$B$70,2,0))) -> M12A4 | G15: =IF(OR($B15=0,G$3=0),"",_xlfn.CONCAT($B15,VLOOKUP(G$2,$A$4:$B$70,2,0))) -> M12I5 | H15: =IF(OR($B15=0,H$3=0),"",_xlfn.CONCAT($B15,VLOOKUP(H$2,$A$4:$B$70,2,0))) -> M12K6 | I15: =IF(OR($B15=0,I$3=0),"",_xlfn.CONCAT($B15,VLOOKUP(I$2,$A$4:$B$70,2,0))) -> M12T7 | J15: =IF(OR($B15=0,J$3=0),"",_xlfn.CONCAT($B15,VLOOKUP(J$2,$A$4:$B$70,2,0))) -> M12F8 | ... AV15: =IF(OR($B15=0,AV$3=0),"",_xlfn.CONCAT($B15,VLOOKUP(AV$2,$A$4:$B$70,2,0)))
A16: =A15+1 -> 13 | B16: =Links!G15 -> G13 | C16: =IF(OR($B16=0,C$3=0),"",_xlfn.CONCAT($B16,VLOOKUP(C$2,$A$4:$B$70,2,0))) -> G13A1 | D16: =IF(OR($B16=0,D$3=0),"",_xlfn.CONCAT($B16,VLOOKUP(D$2,$A$4:$B$70,2,0))) -> G13E2 | E16: =IF(OR($B16=0,E$3=0),"",_xlfn.CONCAT($B16,VLOOKUP(E$2,$A$4:$B$70,2,0))) -> G13W3 | F16: =IF(OR($B16=0,F$3=0),"",_xlfn.CONCAT($B16,VLOOKUP(F$2,$A$4:$B$70,2,0))) -> G13A4 | G16: =IF(OR($B16=0,G$3=0),"",_xlfn.CONCAT($B16,VLOOKUP(G$2,$A$4:$B$70,2,0))) -> G13I5 | H16: =IF(OR($B16=0,H$3=0),"",_xlfn.CONCAT($B16,VLOOKUP(H$2,$A$4:$B$70,2,0))) -> G13K6 | I16: =IF(OR($B16=0,I$3=0),"",_xlfn.CONCAT($B16,VLOOKUP(I$2,$A$4:$B$70,2,0))) -> G13T7 | J16: =IF(OR($B16=0,J$3=0),"",_xlfn.CONCAT($B16,VLOOKUP(J$2,$A$4:$B$70,2,0))) -> G13F8 | ... AV16: =IF(OR($B16=0,AV$3=0),"",_xlfn.CONCAT($B16,VLOOKUP(AV$2,$A$4:$B$70,2,0)))
... A45: =A44+1 -> 42 | B45: =Links!G44 -> M42 | C45: =IF(OR($B45=0,C$3=0),"",_xlfn.CONCAT($B45,VLOOKUP(C$2,$A$4:$B$70,2,0))) -> M42A1 | D45: =IF(OR($B45=0,D$3=0),"",_xlfn.CONCAT($B45,VLOOKUP(D$2,$A$4:$B$70,2,0))) -> M42E2 | E45: =IF(OR($B45=0,E$3=0),"",_xlfn.CONCAT($B45,VLOOKUP(E$2,$A$4:$B$70,2,0))) -> M42W3 | F45: =IF(OR($B45=0,F$3=0),"",_xlfn.CONCAT($B45,VLOOKUP(F$2,$A$4:$B$70,2,0))) -> M42A4 | G45: =IF(OR($B45=0,G$3=0),"",_xlfn.CONCAT($B45,VLOOKUP(G$2,$A$4:$B$70,2,0))) -> M42I5 | H45: =IF(OR($B45=0,H$3=0),"",_xlfn.CONCAT($B45,VLOOKUP(H$2,$A$4:$B$70,2,0))) -> M42K6 | I45: =IF(OR($B45=0,I$3=0),"",_xlfn.CONCAT($B45,VLOOKUP(I$2,$A$4:$B$70,2,0))) -> M42T7 | J45: =IF(OR($B45=0,J$3=0),"",_xlfn.CONCAT($B45,VLOOKUP(J$2,$A$4:$B$70,2,0))) -> M42F8 | ... AV45: =IF(OR($B45=0,AV$3=0),"",_xlfn.CONCAT($B45,VLOOKUP(AV$2,$A$4:$B$70,2,0)))
C46: =IF(OR($B46=0,C$3=0),"",_xlfn.CONCAT($B46,VLOOKUP(C$2,$A$4:$B$70,2,0))) | D46: =IF(OR($B46=0,D$3=0),"",_xlfn.CONCAT($B46,VLOOKUP(D$2,$A$4:$B$70,2,0))) | E46: =IF(OR($B46=0,E$3=0),"",_xlfn.CONCAT($B46,VLOOKUP(E$2,$A$4:$B$70,2,0))) | F46: =IF(OR($B46=0,F$3=0),"",_xlfn.CONCAT($B46,VLOOKUP(F$2,$A$4:$B$70,2,0))) | G46: =IF(OR($B46=0,G$3=0),"",_xlfn.CONCAT($B46,VLOOKUP(G$2,$A$4:$B$70,2,0))) | H46: =IF(OR($B46=0,H$3=0),"",_xlfn.CONCAT($B46,VLOOKUP(H$2,$A$4:$B$70,2,0))) | I46: =IF(OR($B46=0,I$3=0),"",_xlfn.CONCAT($B46,VLOOKUP(I$2,$A$4:$B$70,2,0))) | J46: =IF(OR($B46=0,J$3=0),"",_xlfn.CONCAT($B46,VLOOKUP(J$2,$A$4:$B$70,2,0))) | ... AV46: =IF(OR($B46=0,AV$3=0),"",_xlfn.CONCAT($B46,VLOOKUP(AV$2,$A$4:$B$70,2,0)))
C47: =IF(OR($B47=0,C$3=0),"",_xlfn.CONCAT($B47,VLOOKUP(C$2,$A$4:$B$70,2,0))) | D47: =IF(OR($B47=0,D$3=0),"",_xlfn.CONCAT($B47,VLOOKUP(D$2,$A$4:$B$70,2,0))) | E47: =IF(OR($B47=0,E$3=0),"",_xlfn.CONCAT($B47,VLOOKUP(E$2,$A$4:$B$70,2,0))) | F47: =IF(OR($B47=0,F$3=0),"",_xlfn.CONCAT($B47,VLOOKUP(F$2,$A$4:$B$70,2,0))) | G47: =IF(OR($B47=0,G$3=0),"",_xlfn.CONCAT($B47,VLOOKUP(G$2,$A$4:$B$70,2,0))) | H47: =IF(OR($B47=0,H$3=0),"",_xlfn.CONCAT($B47,VLOOKUP(H$2,$A$4:$B$70,2,0))) | I47: =IF(OR($B47=0,I$3=0),"",_xlfn.CONCAT($B47,VLOOKUP(I$2,$A$4:$B$70,2,0))) | J47: =IF(OR($B47=0,J$3=0),"",_xlfn.CONCAT($B47,VLOOKUP(J$2,$A$4:$B$70,2,0))) | ... AV47: =IF(OR($B47=0,AV$3=0),"",_xlfn.CONCAT($B47,VLOOKUP(AV$2,$A$4:$B$70,2,0)))
C48: =IF(OR($B48=0,C$3=0),"",_xlfn.CONCAT($B48,VLOOKUP(C$2,$A$4:$B$70,2,0))) | D48: =IF(OR($B48=0,D$3=0),"",_xlfn.CONCAT($B48,VLOOKUP(D$2,$A$4:$B$70,2,0))) | E48: =IF(OR($B48=0,E$3=0),"",_xlfn.CONCAT($B48,VLOOKUP(E$2,$A$4:$B$70,2,0))) | F48: =IF(OR($B48=0,F$3=0),"",_xlfn.CONCAT($B48,VLOOKUP(F$2,$A$4:$B$70,2,0))) | G48: =IF(OR($B48=0,G$3=0),"",_xlfn.CONCAT($B48,VLOOKUP(G$2,$A$4:$B$70,2,0))) | H48: =IF(OR($B48=0,H$3=0),"",_xlfn.CONCAT($B48,VLOOKUP(H$2,$A$4:$B$70,2,0))) | I48: =IF(OR($B48=0,I$3=0),"",_xlfn.CONCAT($B48,VLOOKUP(I$2,$A$4:$B$70,2,0))) | J48: =IF(OR($B48=0,J$3=0),"",_xlfn.CONCAT($B48,VLOOKUP(J$2,$A$4:$B$70,2,0))) | ... AV48: =IF(OR($B48=0,AV$3=0),"",_xlfn.CONCAT($B48,VLOOKUP(AV$2,$A$4:$B$70,2,0)))
C49: =IF(OR($B49=0,C$3=0),"",_xlfn.CONCAT($B49,VLOOKUP(C$2,$A$4:$B$70,2,0))) | D49: =IF(OR($B49=0,D$3=0),"",_xlfn.CONCAT($B49,VLOOKUP(D$2,$A$4:$B$70,2,0))) | E49: =IF(OR($B49=0,E$3=0),"",_xlfn.CONCAT($B49,VLOOKUP(E$2,$A$4:$B$70,2,0))) | F49: =IF(OR($B49=0,F$3=0),"",_xlfn.CONCAT($B49,VLOOKUP(F$2,$A$4:$B$70,2,0))) | G49: =IF(OR($B49=0,G$3=0),"",_xlfn.CONCAT($B49,VLOOKUP(G$2,$A$4:$B$70,2,0))) | H49: =IF(OR($B49=0,H$3=0),"",_xlfn.CONCAT($B49,VLOOKUP(H$2,$A$4:$B$70,2,0))) | I49: =IF(OR($B49=0,I$3=0),"",_xlfn.CONCAT($B49,VLOOKUP(I$2,$A$4:$B$70,2,0))) | J49: =IF(OR($B49=0,J$3=0),"",_xlfn.CONCAT($B49,VLOOKUP(J$2,$A$4:$B$70,2,0))) | ... AV49: =IF(OR($B49=0,AV$3=0),"",_xlfn.CONCAT($B49,VLOOKUP(AV$2,$A$4:$B$70,2,0)))
C50: =IF(OR($B50=0,C$3=0),"",_xlfn.CONCAT($B50,VLOOKUP(C$2,$A$4:$B$70,2,0))) | D50: =IF(OR($B50=0,D$3=0),"",_xlfn.CONCAT($B50,VLOOKUP(D$2,$A$4:$B$70,2,0))) | E50: =IF(OR($B50=0,E$3=0),"",_xlfn.CONCAT($B50,VLOOKUP(E$2,$A$4:$B$70,2,0))) | F50: =IF(OR($B50=0,F$3=0),"",_xlfn.CONCAT($B50,VLOOKUP(F$2,$A$4:$B$70,2,0))) | G50: =IF(OR($B50=0,G$3=0),"",_xlfn.CONCAT($B50,VLOOKUP(G$2,$A$4:$B$70,2,0))) | H50: =IF(OR($B50=0,H$3=0),"",_xlfn.CONCAT($B50,VLOOKUP(H$2,$A$4:$B$70,2,0))) | I50: =IF(OR($B50=0,I$3=0),"",_xlfn.CONCAT($B50,VLOOKUP(I$2,$A$4:$B$70,2,0))) | J50: =IF(OR($B50=0,J$3=0),"",_xlfn.CONCAT($B50,VLOOKUP(J$2,$A$4:$B$70,2,0))) | ... AV50: =IF(OR($B50=0,AV$3=0),"",_xlfn.CONCAT($B50,VLOOKUP(AV$2,$A$4:$B$70,2,0)))
C51: =IF(OR($B51=0,C$3=0),"",_xlfn.CONCAT($B51,VLOOKUP(C$2,$A$4:$B$70,2,0))) | D51: =IF(OR($B51=0,D$3=0),"",_xlfn.CONCAT($B51,VLOOKUP(D$2,$A$4:$B$70,2,0))) | E51: =IF(OR($B51=0,E$3=0),"",_xlfn.CONCAT($B51,VLOOKUP(E$2,$A$4:$B$70,2,0))) | F51: =IF(OR($B51=0,F$3=0),"",_xlfn.CONCAT($B51,VLOOKUP(F$2,$A$4:$B$70,2,0))) | G51: =IF(OR($B51=0,G$3=0),"",_xlfn.CONCAT($B51,VLOOKUP(G$2,$A$4:$B$70,2,0))) | H51: =IF(OR($B51=0,H$3=0),"",_xlfn.CONCAT($B51,VLOOKUP(H$2,$A$4:$B$70,2,0))) | I51: =IF(OR($B51=0,I$3=0),"",_xlfn.CONCAT($B51,VLOOKUP(I$2,$A$4:$B$70,2,0))) | J51: =IF(OR($B51=0,J$3=0),"",_xlfn.CONCAT($B51,VLOOKUP(J$2,$A$4:$B$70,2,0))) | ... AV51: =IF(OR($B51=0,AV$3=0),"",_xlfn.CONCAT($B51,VLOOKUP(AV$2,$A$4:$B$70,2,0)))
C52: =IF(OR($B52=0,C$3=0),"",_xlfn.CONCAT($B52,VLOOKUP(C$2,$A$4:$B$70,2,0))) | D52: =IF(OR($B52=0,D$3=0),"",_xlfn.CONCAT($B52,VLOOKUP(D$2,$A$4:$B$70,2,0))) | E52: =IF(OR($B52=0,E$3=0),"",_xlfn.CONCAT($B52,VLOOKUP(E$2,$A$4:$B$70,2,0))) | F52: =IF(OR($B52=0,F$3=0),"",_xlfn.CONCAT($B52,VLOOKUP(F$2,$A$4:$B$70,2,0))) | G52: =IF(OR($B52=0,G$3=0),"",_xlfn.CONCAT($B52,VLOOKUP(G$2,$A$4:$B$70,2,0))) | H52: =IF(OR($B52=0,H$3=0),"",_xlfn.CONCAT($B52,VLOOKUP(H$2,$A$4:$B$70,2,0))) | I52: =IF(OR($B52=0,I$3=0),"",_xlfn.CONCAT($B52,VLOOKUP(I$2,$A$4:$B$70,2,0))) | J52: =IF(OR($B52=0,J$3=0),"",_xlfn.CONCAT($B52,VLOOKUP(J$2,$A$4:$B$70,2,0))) | ... AV52: =IF(OR($B52=0,AV$3=0),"",_xlfn.CONCAT($B52,VLOOKUP(AV$2,$A$4:$B$70,2,0)))
